[2025-04-11T04:05:10.577+0000] {local_task_job_runner.py:123} INFO - ::group::Pre task execution logs
[2025-04-11T04:05:10.594+0000] {taskinstance.py:2603} INFO - Dependencies all met for dep_context=non-requeueable deps ti=<TaskInstance: etl_dag.data_storing scheduled__2025-04-10T00:00:00+00:00 [queued]>
[2025-04-11T04:05:10.601+0000] {taskinstance.py:2603} INFO - Dependencies all met for dep_context=requeueable deps ti=<TaskInstance: etl_dag.data_storing scheduled__2025-04-10T00:00:00+00:00 [queued]>
[2025-04-11T04:05:10.603+0000] {taskinstance.py:2856} INFO - Starting attempt 16 of 17
[2025-04-11T04:05:10.612+0000] {taskinstance.py:2879} INFO - Executing <Task(_PythonDecoratedOperator): data_storing> on 2025-04-10 00:00:00+00:00
[2025-04-11T04:05:10.620+0000] {warnings.py:112} WARNING - /home/***/.local/lib/python3.12/site-packages/***/task/task_runner/standard_task_runner.py:70: DeprecationWarning: This process (pid=89) is multi-threaded, use of fork() may lead to deadlocks in the child.
  pid = os.fork()

[2025-04-11T04:05:10.623+0000] {standard_task_runner.py:72} INFO - Started process 91 to run task
[2025-04-11T04:05:10.623+0000] {standard_task_runner.py:104} INFO - Running: ['***', 'tasks', 'run', 'etl_dag', 'data_storing', 'scheduled__2025-04-10T00:00:00+00:00', '--job-id', '72', '--raw', '--subdir', 'DAGS_FOLDER/dag_for_workshop.py', '--cfg-path', '/tmp/tmpvmxlpksc']
[2025-04-11T04:05:10.626+0000] {standard_task_runner.py:105} INFO - Job 72: Subtask data_storing
[2025-04-11T04:05:10.690+0000] {task_command.py:467} INFO - Running <TaskInstance: etl_dag.data_storing scheduled__2025-04-10T00:00:00+00:00 [running]> on host d19c1bc262ea
[2025-04-11T04:05:12.098+0000] {taskinstance.py:3122} INFO - Exporting env vars: AIRFLOW_CTX_DAG_EMAIL='example@example.com' AIRFLOW_CTX_DAG_OWNER='***' AIRFLOW_CTX_DAG_ID='etl_dag' AIRFLOW_CTX_TASK_ID='data_storing' AIRFLOW_CTX_EXECUTION_DATE='2025-04-10T00:00:00+00:00' AIRFLOW_CTX_TRY_NUMBER='16' AIRFLOW_CTX_DAG_RUN_ID='scheduled__2025-04-10T00:00:00+00:00'
[2025-04-11T04:05:12.100+0000] {taskinstance.py:731} INFO - ::endgroup::
[2025-04-11T04:05:13.217+0000] {store.py:38} INFO - Starting Google Drive authentication process.
[2025-04-11T04:05:13.219+0000] {store.py:50} INFO - Saved credentials not found, performing web authentication.
[2025-04-11T04:05:13.221+0000] {logging_mixin.py:190} INFO - Your browser has been opened to visit:
[2025-04-11T04:05:13.221+0000] {logging_mixin.py:190} INFO -     https://accounts.google.com/o/oauth2/auth?client_id=128942751751-34t5ej1o2ok3plimh14p3v3gq8v6r8ln.apps.googleusercontent.com&redirect_uri=http%3A%2F%2Flocalhost%3A8080%2F&scope=https%3A%2F%2Fwww.googleapis.com%2Fauth%2Fdrive&access_type=offline&response_type=code&approval_prompt=force
